Workbook
Name rng_Expenses20: '20'!$B$15:$E$22
Name Slicer_Category: #N/A
Name Slicer_Month: #N/A
Name Slicer_Payment_Method: #N/A
Name Slicer_Region: #N/A

Sheet Start
A1: Welcome Instructions for screen readers: Make your first PivotTable. PivotTables are not as hard as you think. After you go through 21 more sheets in this tutorial, you'll learn how to quickly create one. The instructions for each sheet start in cell A1, and each subsequent step is in cell A2, A3, and so on. The instructions will indicate which cells to navigate to for use of a feature, or further reading. To start, press CTRL+PAGE DOWN.
A2: Make your first PivotTable
A3: PivotTables are not as hard as you think. After you walk through these simple steps, you'll know how to quickly create one.
A4: Go back to top by pressing CTRL+HOME. To start the tour, press CTRL+PAGE DOWN.

Sheet 1
A1: What is a PivotTable? In its most basic form, a PivotTable takes data and summarizes it so you can make sense of it, all without typing any formulas!
A2: Cells B10 through E17 contain Data. There are four columns: Date, Buyer, Type, and Amount. Each column has various values for each row.
A3: Cells H10 through I14 contain a PivotTable which summarizes the data. The PivotTable has two columns: Buyer and Sum of Amount. The Buyer column contains the values Dad, Mom, Kelly, and Grand Total; The Sum of Amount column contains the values $20, $544, $270, and $834.
A4: To continue with this tutorial, press CTRL+PAGE DOWN. To go to the previous sheet, press CTRL+PAGE UP.
B10: Date | C10: Buyer | D10: Type | E10: Amount | H10: Buyer | I10: Sum of Amount
B11: 42736 | C11: Mom | D11: Fuel | E11: 74 | H11: Dad | I11: 20
B12: 42750 | C12: Mom | D12: Food | E12: 235 | H12: Mom | I12: 544
B13: 42752 | C13: Dad | D13: Sports | E13: 20 | H13: Kelly | I13: 270
B14: 42756 | C14: Kelly | D14: Books | E14: 125 | H14: Grand Total | I14: 834
B15: 42768 | C15: Mom | D15: Food | E15: 235
B16: 42786 | C16: Kelly | D16: Music | E16: 20
B17: 42791 | C17: Kelly | D17: Tickets | E17: 125

Sheet 2
A1: That was a simple example. Here's a more sophisticated one. This one shows the spending amounts broken down by type of purchase and by buyer.
A2: Cells B10 through E17 contain Data. There are four columns: Date, Buyer, Type, and Amount. Each column has various values for each row.
A3: Cells G10 through K18 contain a more sophisticated PivotTable which summarizes the data. The PivotTable has five columns: Type, Dad, Kelly, Mom, and Grand Total. The Type column contains the values Books, Food, Fuel, Music, Sports, and Tickets. The Dad, Kelly, and Mom columns contain various dollar amounts, and the Grand Total column contains the total dollar amounts for each Type.
A4: To continue with this tutorial, press CTRL+PAGE DOWN. To go to the previous sheet, press CTRL+PAGE UP.
B10: Date | C10: Buyer | D10: Type | E10: Amount | G10: Sum of Amount | H10: Buyer
B11: 42736 | C11: Mom | D11: Fuel | E11: 74 | G11: Type | H11: Dad | I11: Kelly | J11: Mom | K11: Grand Total
B12: 42750 | C12: Mom | D12: Food | E12: 235 | G12: Books | I12: 125 | K12: 125
B13: 42752 | C13: Dad | D13: Sports | E13: 20 | G13: Food | J13: 470 | K13: 470
B14: 42756 | C14: Kelly | D14: Books | E14: 125 | G14: Fuel | J14: 74 | K14: 74
B15: 42768 | C15: Mom | D15: Food | E15: 235 | G15: Music | I15: 20 | K15: 20
B16: 42786 | C16: Kelly | D16: Music | E16: 20 | G16: Sports | H16: 20 | K16: 20
B17: 42791 | C17: Kelly | D17: Tickets | E17: 125 | G17: Tickets | I17: 125 | K17: 125
G18: Grand Total | H18: 20 | I18: 270 | J18: 544 | K18: 834

Sheet 3
A1: There are also PivotCharts, which are a more visual way to summarize and make sense of the data. We won't be covering these, but for now, just know that they're possible to do.
A2: Cells B10 through E17 contain Data. There are four columns: Date, Buyer, Type, and Amount. Each column has various values for each row.
A3: To the right of the data is a PivotChart which summarizes and visualizes the data. To select it, press ALT+H, FD, P. Then use your arrows keys to move to PivotChartExample and press Enter. When you're done, press CTRL G, type A4, then Enter.
A4: To continue with this tutorial, press CTRL+PAGE DOWN. To go to the previous sheet, press CTRL+PAGE UP.
B10: Date | C10: Buyer | D10: Type | E10: Amount | G10: Sum of Amount | H10: Column Labels
B11: 42736 | C11: Mom | D11: Fuel | E11: 74 | G11: Row Labels | H11: Dad | I11: Kelly | J11: Mom | K11: Grand Total
B12: 42750 | C12: Mom | D12: Food | E12: 235 | G12: Books | I12: 125 | K12: 125
B13: 42752 | C13: Dad | D13: Sports | E13: 20 | G13: Food | J13: 470 | K13: 470
B14: 42756 | C14: Kelly | D14: Books | E14: 125 | G14: Fuel | J14: 74 | K14: 74
B15: 42768 | C15: Mom | D15: Food | E15: 235 | G15: Music | I15: 20 | K15: 20
B16: 42786 | C16: Kelly | D16: Music | E16: 20 | G16: Sports | H16: 20 | K16: 20
B17: 42791 | C17: Kelly | D17: Tickets | E17: 125 | G17: Tickets | I17: 125 | K17: 125
G18: Grand Total | H18: 20 | I18: 270 | J18: 544 | K18: 834

Sheet 4
A1: But let's back up. The first step to making a good PivotTable is to make sure the data is in good shape. So, make sure you do the following before you make one:
A2: Cells B10 through E17 contain Data. There are four columns: Date, Buyer, Type, and Amount. Each column has values, no duplicates, and no blanks.
A3: There is a label pointing to the columns that says, "Name your columns." There is also a label pointing to the rows that says, "And make sure there are no duplicate rows, or blank cells."
A4: To continue with this tutorial, press CTRL+PAGE DOWN. To go to the previous sheet, press CTRL+PAGE UP.
B10: Date | C10: Buyer | D10: Type | E10: Amount
B11: 42736 | C11: Mom | D11: Fuel | E11: 74
B12: 42750 | C12: Mom | D12: Food | E12: 235
B13: 42752 | C13: Dad | D13: Sports | E13: 20
B14: 42756 | C14: Kelly | D14: Books | E14: 125
B15: 42768 | C15: Mom | D15: Food | E15: 235
B16: 42786 | C16: Kelly | D16: Music | E16: 20
B17: 42791 | C17: Kelly | D17: Tickets | E17: 125

Sheet 5
A1: Something to keep in mind: Lots of people use the word "column." But to a PivotTable, a column is a "field." Remember this as you progress with the tutorial.
A2: Cells B10 through E17 contain Data. There are four columns: Date, Buyer, Type, and Amount. Each column has a label pointing to it that says "Field."
A3: GOOD TO KNOW: Why the word "field"? It's just a traditional term used when working with data and database applications. The PivotTable menus and buttons use the word "field" a lot. So if you get used to it now, it will make things easier as you make PivotTables.
A4: To continue with this tutorial, press CTRL+PAGE DOWN. To go to the previous sheet, press CTRL+PAGE UP.
B10: Date | C10: Buyer | D10: Type | E10: Amount
B11: 42736 | C11: Mom | D11: Fuel | E11: 74
B12: 42750 | C12: Mom | D12: Food | E12: 235
B13: 42752 | C13: Dad | D13: Sports | E13: 20
B14: 42756 | C14: Kelly | D14: Books | E14: 125
B15: 42768 | C15: Mom | D15: Food | E15: 235
B16: 42786 | C16: Kelly | D16: Music | E16: 20
B17: 42791 | C17: Kelly | D17: Tickets | E17: 125

Sheet 6
A1: Let's focus on one of the fields. One of the fields below, the Amount field, is probably the most important. Wouldn't it be great if it was summed up?
A2: Cells B10 through E17 contain Data. There are four columns: Date, Buyer, Type, and Amount. The Amount column has a label pointing to it that says "This field should be summed up."
A3: To continue with this tutorial, press CTRL+PAGE DOWN. To go to the previous sheet, press CTRL+PAGE UP.
B10: Date | C10: Buyer | D10: Type | E10: Amount
B11: 42736 | C11: Mom | D11: Fuel | E11: 74
B12: 42750 | C12: Mom | D12: Food | E12: 235
B13: 42752 | C13: Dad | D13: Sports | E13: 20
B14: 42756 | C14: Kelly | D14: Books | E14: 125
B15: 42768 | C15: Mom | D15: Food | E15: 235
B16: 42786 | C16: Kelly | D16: Music | E16: 20
B17: 42791 | C17: Kelly | D17: Tickets | E17: 125

Sheet 7
A1: So we did that. We summed up the Amount field with a PivotTable. (Really?) Yes. Sum of Amount and $834 make up a small PivotTable that totals up the Amount field.
A2: Cells B10 through E17 contain Data. There are four columns: Date, Buyer, Type, and Amount. Each column has various values for each row.
A3: Cells H10 and H11 contain a PivotTable which totals the Amount column. The PivotTable has one column: Sum of Amount. And that column only has one value: $834. There is a label pointing to the PivotTable that says, "It may not look like much, but this is a PivotTable."
A4: To continue with this tutorial, press CTRL+PAGE DOWN. To go to the previous sheet, press CTRL+PAGE UP.
B10: Date | C10: Buyer | D10: Type | E10: Amount | H10: Sum of Amount
B11: 42736 | C11: Mom | D11: Fuel | E11: 74 | H11: 834
B12: 42750 | C12: Mom | D12: Food | E12: 235
B13: 42752 | C13: Dad | D13: Sports | E13: 20
B14: 42756 | C14: Kelly | D14: Books | E14: 125
B15: 42768 | C15: Mom | D15: Food | E15: 235
B16: 42786 | C16: Kelly | D16: Music | E16: 20
B17: 42791 | C17: Kelly | D17: Tickets | E17: 125

Sheet 8
A1: Why make such a small PivotTable? Because it emphasizes the concept of a PivotTable value field. If one of the fields in your data contains numeric values, a PivotTable can total it up. When it does this, it's called a PivotTable value field.
A2: Cells B11 through E18 contain Data. There are four columns: Date, Buyer, Type, and Amount. Each column has various values for each row. There is a label pointing to the Amount column that says, "This field contains numeric values…"
A3: Cells H11 and H12 contain a PivotTable which totals the Amount column. The PivotTable has one column: Sum of Amount. And that column only has one value: $834. There is a label pointing to the PivotTable that says, "…and this PivotTable made it into a 'value field.'"
A4: To continue with this tutorial, press CTRL+PAGE DOWN. To go to the previous sheet, press CTRL+PAGE UP.
B11: Date | C11: Buyer | D11: Type | E11: Amount | H11: Sum of Amount
B12: 42736 | C12: Mom | D12: Fuel | E12: 74 | H12: 834
B13: 42750 | C13: Mom | D13: Food | E13: 235
B14: 42752 | C14: Dad | D14: Sports | E14: 20
B15: 42756 | C15: Kelly | D15: Books | E15: 125
B16: 42768 | C16: Mom | D16: Food | E16: 235
B17: 42786 | C17: Kelly | D17: Music | E17: 20
B18: 42791 | C18: Kelly | D18: Tickets | E18: 125

Sheet 9
A1: PivotTables start getting interesting when you add conditions that divide or break down the value field. In this case, we added a new condition of Buyer to divide the value field.
A2: Cells B11 through E18 contain Data. There are four columns: Date, Buyer, Type, and Amount. Each column has various values for each row.
A3: Cells H11 through I15 contain a PivotTable which summarizes the data. The PivotTable has two columns: Buyer and Sum of Amount. The Buyer column contains the values Dad, Kelly, Mom, and Grand Total; the Sum of Amount column contains the values $20, $270, $544, and $834. There is a label pointing to the Buyer column that says, "We added a condition here to divide the value field by 'Buyer.'" There is also a label that points to the Sum of Amount column that says "Value field."
A4: To continue with this tutorial, press CTRL+PAGE DOWN. To go to the previous sheet, press CTRL+PAGE UP.
B11: Date | C11: Buyer | D11: Type | E11: Amount | H11: Buyer | I11: Sum of Amount
B12: 42736 | C12: Mom | D12: Fuel | E12: 74 | H12: Dad | I12: 20
B13: 42750 | C13: Mom | D13: Food | E13: 235 | H13: Kelly | I13: 270
B14: 42752 | C14: Dad | D14: Sports | E14: 20 | H14: Mom | I14: 544
B15: 42756 | C15: Kelly | D15: Books | E15: 125 | H15: Grand Total | I15: 834
B16: 42768 | C16: Mom | D16: Food | E16: 235
B17: 42786 | C17: Kelly | D17: Music | E17: 20
B18: 42791 | C18: Kelly | D18: Tickets | E18: 125

Sheet 10
A1: And here's another version of the PivotTable, but this time we added the condition of Type to see how much was spent for each type of purchase.
A2: Cells B10 through E17 contain Data. There are four columns: Date, Buyer, Type, and Amount. Each column has various values for each row.
A3: Cells H10 through I17 contain a PivotTable which summarizes the data. The PivotTable has two columns: Type and Sum of Amount. The Type column contains the values Books, Food, Fuel, Music, Sports, Tickets, and Grand Total; the Sum of Amount column contains the values $125, $470, $74, $20, $20, $125, and $834. There is a label pointing to the Type column that says, "We added a condition here to divide the value field by 'Type.'" There is also a label that points to the Sum of Amount column that says, "Value field."
A4: To continue with this tutorial, press CTRL+PAGE DOWN. To go to the previous sheet, press CTRL+PAGE UP.
B10: Date | C10: Buyer | D10: Type | E10: Amount | H10: Type | I10: Sum of Amount
B11: 42736 | C11: Mom | D11: Fuel | E11: 74 | H11: Books | I11: 125
B12: 42750 | C12: Mom | D12: Food | E12: 235 | H12: Food | I12: 470
B13: 42752 | C13: Dad | D13: Sports | E13: 20 | H13: Fuel | I13: 74
B14: 42756 | C14: Kelly | D14: Books | E14: 125 | H14: Music | I14: 20
B15: 42768 | C15: Mom | D15: Food | E15: 235 | H15: Sports | I15: 20
B16: 42786 | C16: Kelly | D16: Music | E16: 20 | H16: Tickets | I16: 125
B17: 42791 | C17: Kelly | D17: Tickets | E17: 125 | H17: Grand Total | I17: 834

Sheet 11
A1: Another PivotTable term: The conditions we've added so far are called PivotTable row fields. In these examples, the row field breaks down, or divides, the value field.
A2: Cells B10 through E17 contain Data. There are four columns: Date, Buyer, Type, and Amount. Each column has various values for each row.
A3: Cells H10 through I14 contain a PivotTable which summarizes the data. The PivotTable has two columns: Buyer, and Sum of Amount. The Buyer column contains the values Dad, Kelly, Mom, and Grand Total; the Sum of Amount column contains the values $20, $270, $544, and $834. There is a label pointing to the Buyer column that says, "Row field." There is also a label that points to the Sum of Amount column that says "Value field."
A4: To continue with this tutorial, press CTRL+PAGE DOWN. To go to the previous sheet, press CTRL+PAGE UP.
B10: Date | C10: Buyer | D10: Type | E10: Amount | H10: Buyer | I10: Sum of Amount
B11: 42736 | C11: Mom | D11: Fuel | E11: 74 | H11: Dad | I11: 20
B12: 42750 | C12: Mom | D12: Food | E12: 235 | H12: Kelly | I12: 270
B13: 42752 | C13: Dad | D13: Sports | E13: 20 | H13: Mom | I13: 544
B14: 42756 | C14: Kelly | D14: Books | E14: 125 | H14: Grand Total | I14: 834
B15: 42768 | C15: Mom | D15: Food | E15: 235
B16: 42786 | C16: Kelly | D16: Music | E16: 20
B17: 42791 | C17: Kelly | D17: Tickets | E17: 125

Sheet 12
A1: Let's review. You'll learn how to actually make a PivotTable in a few moments. But let's review the concepts we've taught you so far:
A2: Cells B10 through E17 contain Data. There are four columns: Date, Buyer, Type, and Amount. Each column has various values for each row. There is a label pointing to the data that says, "First start with good data."
A3: Cells H10 through I14 contain a PivotTable which summarizes the data.
A4: The PivotTable has two columns: Buyer, and Sum of Amount. The Buyer column contains the values Dad, Kelly, Mom, and Grand Total. The Sum of Amount column contains the values $20, $270, $544 and $834. There is a label pointing to the Buyer column that says, "A 'row field' breaks down..." There is also a label that points to the Sum of Amount column that says, "...a 'value field.'"
A5: To continue with this tutorial, press CTRL+PAGE DOWN. To go to the previous sheet, press CTRL+PAGE UP.
B10: Date | C10: Buyer | D10: Type | E10: Amount | H10: Buyer | I10: Sum of Amount
B11: 42736 | C11: Mom | D11: Fuel | E11: 74 | H11: Dad | I11: 20
B12: 42750 | C12: Mom | D12: Food | E12: 235 | H12: Kelly | I12: 270
B13: 42752 | C13: Dad | D13: Sports | E13: 20 | H13: Mom | I13: 544
B14: 42756 | C14: Kelly | D14: Books | E14: 125 | H14: Grand Total | I14: 834
B15: 42768 | C15: Mom | D15: Food | E15: 235
B16: 42786 | C16: Kelly | D16: Music | E16: 20
B17: 42791 | C17: Kelly | D17: Tickets | E17: 125

Sheet 13
A1: When you create a PivotTable in a moment, you'll see the PivotTable Fields List. It's not just a list though, it's a more like a panel. At the top you'll see the fields from your data.
A2: Cells C14 through F21 contain Data. There are four columns: Date, Buyer, Type, and Amount. Each column has various values for each row.
A3: There is a label pointing to the data fields that says, "Excel looks at your data..."
A4: There is an arrow that starts at the top of the field names and points to the same field names in a picture of the PivotTable Fields List.
A5: To continue with this tutorial, press CTRL+PAGE DOWN. To go to the previous sheet, press CTRL+PAGE UP.
C14: Date | D14: Buyer | E14: Type | F14: Amount
C15: 42736 | D15: Mom | E15: Fuel | F15: 74
C16: 42750 | D16: Mom | E16: Food | F16: 235
C17: 42752 | D17: Dad | E17: Sports | F17: 20
C18: 42756 | D18: Kelly | E18: Books | F18: 125
C19: 42768 | D19: Mom | E19: Food | F19: 235
C20: 42786 | D20: Kelly | E20: Music | F20: 20
C21: 42791 | D21: Kelly | E21: Tickets | F21: 125

Sheet 14
A1: Don't do this now but in a couple steps, you'll work with a PivotTable. The first thing you'll do is create a value field. You'll do that by dragging the Amount field to the Values area.
A2: A PivotTable Fields List image shows an arrow cursor dragging the Amount field to the Values area.
A3: BEST PRACTICE: In your own situations, if you're ever unsure how to start a PivotTable, think about creating the value field first. Fields that are best for value fields are ones with numerical amounts. In this example, Amount is the best one. The other fields (Date, Buyer, Type) don't contain numerical values, so they aren't the best ones to use for the value field.
A4: To continue with this tutorial, press CTRL+PAGE DOWN. To go to the previous sheet, press CTRL+PAGE UP.

Sheet 15
A1: After you drag the field to the Values area, "Sum of Am..." will appear at the bottom of the PivotTable Fields List. (Sometimes Excel doesn't have room to show the full name, which is really "Sum of Amount.")
A2: Cells E12 and E13 contain a PivotTable which totals the Amount column. The PivotTable has one column: Sum of Amount. And that column only has one value: $834. There is a label pointing to the PivotTable that says, "Creating a value field sums up the 'Amount' field and makes a small PivotTable like this."
A3: PivotTable Fields List image shows "Sum of Am…" highlighted in the Values area.
A4: To continue with this tutorial, press CTRL+PAGE DOWN. To go to the previous sheet, press CTRL+PAGE UP.
E12: Sum of Amount
E13: 834

Sheet 16
A1: Then you'll want a condition to divide the value field by. And to do that, you drag any of the other fields down to the Rows area.
A2: PivotTable Fields List image shows an arrow cursor dragging the Buyer field to the Rows area. The Rows area is highlighted.
A3: Cells E12 and E13 contain a PivotTable which totals the Amount column. The PivotTable has one column: Sum of Amount. And that column only has one value: $834.
A4: To continue with this tutorial, press CTRL+PAGE DOWN. To go to the previous sheet, press CTRL+PAGE UP.
E12: Sum of Amount
E13: 834

Sheet 17
A1: Now that the Buyer field is in the Rows area, you'll see that the PivotTable shows each buyer's amount. You'll see how easy this is in a second...and the great part about this is it doesn't require typing any formulas!
A2: Cells D12 and E16 contain a PivotTable. The PivotTable has two columns: Row Labels and Sum of Amount. Row Labels contains the values Dad, Kelly, Mom, and Grand Total. Sum of Amount contains the values $20, $270, $544, and $834.
A3: There is a label pointing to the Row Labels column that says, "The row field 'Buyer'"; another label points to the Sum of Amount column that says, "Divides the value field 'Sum of Amount.'"
A4: A PivotTable Fields List image shows "Buyer" highlighted in the Rows area.
A5: To continue with this tutorial, press CTRL+PAGE DOWN. To go to the previous sheet, press CTRL+PAGE UP.
D12: Row Labels | E12: Sum of Amount
D13: Dad | E13: 20
D14: Kelly | E14: 270
D15: Mom | E15: 544
D16: Grand Total | E16: 834

Sheet 18
A1: WORK WITH THE PIVOTTABLE FIELDS LIST
A2: Cells B14 through E21 contain Data. There are four columns: Date, Buyer, Type, and Amount. Each column has various values for each row.
A3: 1. In cells H14 through J31 is the PivotTable Area. Navigate to any of those cells.
A4: 2. Press ALT+JT, L to launch the PivotTable Fields List. Focus will default to the Search text box: "Type words to search for" edit. Do not type anything, instead, tab once.
A5: 3. Press your arrow keys to move to the Amount field. Press SPACEBAR to add the Amount field to the Values area.
A6: 4. Press arrows keys to move to the Buyer field. Press SPACEBAR to add the Buyer field to the Rows area. Press ESC key to exit PivotTable Fields pane.
A7: Note: After you complete steps 3 and 4, you may have to make the columns wider to see all of the text and numbers in the PivotTable. (This is a common "extra step" you have to do after creating a PivotTable.)
A8: To continue with this tutorial, press CTRL+PAGE DOWN. To go to the previous sheet, press CTRL+PAGE UP.
H12: =IF(AND($H$14="Buyer",$I$18=834),"Good job! You placed the fields correctly."," ") -> Good job! You placed the fields correctly.
B14: Date | C14: Buyer | D14: Type | E14: Amount | H14: Buyer | I14: Sum of Amount
B15: 42736 | C15: Mom | D15: Fuel | E15: 74 | H15: Dad | I15: 20
B16: 42750 | C16: Mom | D16: Food | E16: 235 | H16: Kelly | I16: 270
B17: 42752 | C17: Dad | D17: Sports | E17: 20 | H17: Mom | I17: 544
B18: 42756 | C18: Kelly | D18: Books | E18: 125 | H18: Grand Total | I18: 834
B19: 42768 | C19: Mom | D19: Food | E19: 235
B20: 42786 | C20: Kelly | D20: Music | E20: 20
B21: 42791 | C21: Kelly | D21: Tickets | E21: 125

Sheet 19
A1: On the next step, you'll create a PivotTable from scratch. And when you do, there's something to keep in mind: Excel puts PivotTables on a new, separate sheet to the left of the sheet you are on.
A2: There is a picture that shows 4 sheet tabs named 17, 18, 19, 20, and Learn More. 20 is the active tab.
A3: There is a caption under the picture that says, "For example, let's say your data is on a sheet named "20." If you created a PivotTable…"
A4: There is a picture that shows a new sheet tab called "Sheet12" that is in between sheet 19 and 20.
A5: If you created a PivotTable, Excel would put it on a new sheet to the left. It would name it "Sheet" and then assign a number to it like "12", "13," etc. You can always select the sheet, Alt+H, O, R, and name it something else like "PivotTable."
A6: WHY DOES THIS HAPPEN? Well, the full name for a PivotTable is: "PivotTable Report." A report is based on data, and typically people like to see the reports separately from all of the data itself. Now, it is possible to put PivotTables on the same sheet as the data. But most of the time, PivotTables need a lot of space, so putting them on a new sheet is a good idea.
A7: To continue with this tutorial, press CTRL+PAGE DOWN. To go to the previous sheet, press CTRL+PAGE UP.

Sheet Sheet1
A3: Row Labels | B3: Sum of Amount
A4: Dad | B4: 20
A5: Kelly | B5: 270
A6: Mom | B6: 544
A7: Grand Total | B7: 834
A10: Product | B10: Price | D10: Price/Day | E10: Day 1 | F10: Day 2
A11: A | B11: 100 | D11: A | E11: =$B11*(1-B$15) -> 80 | F11: =$B11*(1-C$15) -> 90
A12: B | B12: 50 | D12: B | E12: =$B12*(1-B$15) -> 40 | F12: =$B12*(1-C$15) -> 45
B14: Day 1 | C14: Day 2
A15: Discount | B15: 0.2 | C15: 0.1
A18: Id | B18: F_name | C18: S_name | D18: Sex | E18: DOB | F18: Math marks | G18: Physics marks | H18: Chemistry marks | I18: Column9 | J18: Column10 | K18: Sum
F19: 45 | G19: 22 | H19: 33 | K19: =Score12[[#This Row],[Math marks]]+Score12[[#This Row],[Physics marks]]+Score12[[#This Row],[Chemistry marks]] -> 100
F20: 56 | G20: 44 | H20: 45 | K20: =Score12[[#This Row],[Math marks]]+Score12[[#This Row],[Physics marks]]+Score12[[#This Row],[Chemistry marks]] -> 145
F21: 78 | G21: 76 | H21: 67 | K21: =Score12[[#This Row],[Math marks]]+Score12[[#This Row],[Physics marks]]+Score12[[#This Row],[Chemistry marks]] -> 221
F22: 99 | G22: 88 | H22: 89 | K22: =Score12[[#This Row],[Math marks]]+Score12[[#This Row],[Physics marks]]+Score12[[#This Row],[Chemistry marks]] -> 276
F23: 22 | G23: 45 | H23: 12 | K23: =Score12[[#This Row],[Math marks]]+Score12[[#This Row],[Physics marks]]+Score12[[#This Row],[Chemistry marks]] -> 79
F24: 34 | G24: 85 | H24: 44 | K24: =Score12[[#This Row],[Math marks]]+Score12[[#This Row],[Physics marks]]+Score12[[#This Row],[Chemistry marks]] -> 163
F25: 76 | G25: 23 | H25: 55 | K25: =Score12[[#This Row],[Math marks]]+Score12[[#This Row],[Physics marks]]+Score12[[#This Row],[Chemistry marks]] -> 154
F26: 99 | G26: 43 | H26: 66 | K26: =Score12[[#This Row],[Math marks]]+Score12[[#This Row],[Physics marks]]+Score12[[#This Row],[Chemistry marks]] -> 208
F27: 12 | G27: 90 | H27: 56 | K27: =Score12[[#This Row],[Math marks]]+Score12[[#This Row],[Physics marks]]+Score12[[#This Row],[Chemistry marks]] -> 158
F28: 45 | G28: 70 | H28: 77 | K28: =Score12[[#This Row],[Math marks]]+Score12[[#This Row],[Physics marks]]+Score12[[#This Row],[Chemistry marks]] -> 192
F29: 22 | G29: 56 | H29: 88 | K29: =Score12[[#This Row],[Math marks]]+Score12[[#This Row],[Physics marks]]+Score12[[#This Row],[Chemistry marks]] -> 166
F30: 44 | G30: 74 | H30: 27 | K30: =Score12[[#This Row],[Math marks]]+Score12[[#This Row],[Physics marks]]+Score12[[#This Row],[Chemistry marks]] -> 145
A31: Total | F31: =SUM(Score12[Math marks]) -> 632 | K31: =SUBTOTAL(109,Score12[Sum]) -> 2007
G32: =G19-SUM(G20:G21:G30) -> -672
A35: F_Name | B35: S_Name | C35: Sex | D35: DOB | E35: Maths Marks | F35: Physics Marks | G35: Chemistry Marks | H35: Location | I35: Stream | J35: Column1
A36: A | B36: P | C36: Male | D36: 37952 | E36: 23 | F36: 58 | G36: 21 | H36: Bangalore | I36: Biology
A37: A | B37: P | C37: Female | D37: 37097 | E37: 29 | F37: 56 | G37: 34 | H37: Bangalore | I37: Commerce
A38: A | B38: P | C38: Male | D38: 37028 | E38: 57 | F38: 30 | G38: 15 | H38: Bangalore | I38: Biology
A39: A | B39: P | C39: Female | D39: 37823 | E39: 18 | F39: 56 | G39: 56 | H39: Bangalore | I39: Maths
A40: A | B40: P | C40: Male | D40: 37292 | E40: 18 | F40: 86 | G40: 48 | H40: Bangalore | I40: Biology
A41: A | B41: P | C41: Male | D41: 36823 | E41: 36 | F41: 76 | G41: 18 | H41: Bangalore | I41: Biology
A42: A | B42: P | C42: Male | D42: 37579 | E42: 43 | F42: 60 | G42: 12 | H42: Bangalore | I42: Biology
A43: A | B43: P | C43: Male | D43: 37181 | E43: 48 | F43: 23 | G43: 1 | H43: Bangalore | I43: Biology
A44: A | B44: P | C44: Male | D44: 36685 | E44: 73 | F44: 14 | G44: 86 | H44: Bangalore | I44: Biology
A45: A | B45: P | C45: Male | D45: 37646 | E45: 73 | F45: 62 | G45: 19 | H45: Bangalore | I45: Biology
A46: A | B46: P | C46: Male | D46: 36728 | E46: 79 | F46: 61 | G46: 93 | H46: Bangalore | I46: Biology
A47: A | B47: P | C47: Male | D47: 37139 | E47: 98 | F47: 44 | G47: 13 | H47: Bangalore | I47: Biology
B50: Day | C50: Month | D50: Year | E50: Date
B51: 5 | C51: 2 | D51: 2001
...

Sheet Sheet2
A1: Advanced Filter | H1: Sales Value
H2: >300
A5: Channel | B5: Product | C5: Date | D5: Sales Value
A6: Website | B6: Shirt blue | C6: 43313 | D6: 200
A7: Store | B7: Shirt white | C7: 43313 | D7: 250
A8: Affiliate site | B8: Pants Blue | C8: 43405 | D8: 300
A9: Store | B9: Shirt blue | C9: 43375 | D9: 260
A10: Affiliate site | B10: Shirt yellow | C10: 43375 | D10: 270
A11: Website | B11: Shirt blue | C11: 12/20/2017 | D11: 280
A12: Store | B12: Pants Blue | C12: 42746 | D12: 100
A13: Store | B13: Shirt blue | C13: 42746 | D13: 500
A14: Website | B14: Shirt yellow | C14: 42746 | D14: 410
A15: Store | B15: Pants Black | C15: 12/20/2017 | D15: 300
A16: Affiliate site | B16: Pants Blue | C16: 12/20/2017 | D16: 400
A17: Store | B17: Shirt white | C17: 12/20/2017 | D17: 100
A18: Store | B18: Pants Black | C18: 43313 | D18: 401
A19: Affiliate site | B19: Pants Blue | C19: 43313 | D19: 430
A20: Store | B20: Shirt blue | C20: 43313 | D20: 285
A21: Affiliate site | B21: Shirt white | C21: 43405 | D21: 344
A22: Store | B22: Shirt white | C22: 43375 | D22: 304
A23: Store | B23: Pants Blue | C23: 43374 | D23: 431
A24: Affiliate site | B24: Shirt yellow | C24: 43374 | D24: 298
A25: Store | B25: Shirt yellow | C25: 43374 | D25: 258
A26: Store | B26: Pants Black | C26: 43374 | D26: 251
A27: Store | B27: Pants Blue | C27: 43020 | D27: 260
A28: Affiliate site | B28: Shirt white | C28: 43020 | D28: 415
A29: Store | B29: Pants Black | C29: 43019 | D29: 266
... A31: Affiliate site | B31: Shirt white | C31: 43313 | D31: 429
A34: SORT BASICS
A36: Division | B36: Region | C36: Apps | D36: Revenue
A37: Productivity | B37: North America | C37: WenCaL | D37: 3155
A38: Productivity | B38: Asia | C38: Blend | D38: 8132
A39: Productivity | B39: Europe | C39: WenCaL | D39: 8532
A40: Productivity | B40: South America | C40: Sleops | D40: 28523
A41: Productivity | B41: South America | C41: WenCaL | D41: 46652
A42: Productivity | B42: Asia | C42: WenCaL | D42: 47296
A43: Productivity | B43: North America | C43: Sleops | D43: 49144
A44: Productivity | B44: North America | C44: Blend | D44: 49988
A45: Utility | B45: Asia | C45: Accord | D45: 3000
A46: Utility | B46: Europe | C46: Twenty20 | D46: 13500
...

Sheet Student Marksheet 
B2: STUDENT PERFORMANCE DASHBOARD
B4: Names | C4: OS | D4: TAFL | E4: Java | F4: Cyber | G4: TC | H4: Total | I4: % | J4: Pass/Fail | K4: Grade | L4: Rank | M4: Performance
B5: Rohan Singhal | C5: 78 | D5: 82 | E5: 75 | F5: 88 | G5: 80 | H5: =SUM(Table19[[#This Row],[OS]:[TC]]) -> 403 | I5: =Table19[[#This Row],[Total]]/5 -> 80.6 | J5: =IF(Table19[[#This Row],[%]]>60,"Pass","Fail") -> Pass | K5: =IF(I6>=90,"A",IF(I6>=75,"B",IF(I6>=60,"C",IF(I6>=40,"D","F")))) -> C | L5: =RANK(I5,$I$5:$I$56,) -> 25
B6: Riyan Verma | C6: 65 | D6: 72 | E6: 69 | F6: 74 | G6: 70 | H6: =SUM(Table19[[#This Row],[OS]:[TC]]) -> 350 | I6: =Table19[[#This Row],[Total]]/5 -> 70 | J6: =IF(Table19[[#This Row],[%]]>60,"Pass","Fail") -> Pass | K6: =IF(I7>=90,"A",IF(I7>=60,"B",IF(I7>=50,"C",IF(I7>=30,"D","F")))) -> A | L6: =RANK(I6,$I$5:$I$56,) -> 36
B7: Kavya Singh | C7: 91 | D7: 89 | E7: 94 | F7: 90 | G7: 92 | H7: =SUM(Table19[[#This Row],[OS]:[TC]]) -> 456 | I7: =Table19[[#This Row],[Total]]/5 -> 91.2 | J7: =IF(Table19[[#This Row],[%]]>60,"Pass","Fail") -> Pass | K7: =IF(I8>=90,"A",IF(I8>=60,"B",IF(I8>=50,"C",IF(I8>=30,"D","F")))) -> C | L7: =RANK(I7,$I$5:$I$56,) -> 11
B8: Dev Patel | C8: 55 | D8: 61 | E8: 58 | F8: 64 | G8: 60 | H8: =SUM(Table19[[#This Row],[OS]:[TC]]) -> 298 | I8: =Table19[[#This Row],[Total]]/5 -> 59.6 | J8: =IF(Table19[[#This Row],[%]]>60,"Pass","Fail") -> Fail | K8: =IF(I9>=90,"A",IF(I9>=60,"B",IF(I9>=50,"C",IF(I9>=30,"D","F")))) -> B | L8: =RANK(I8,$I$5:$I$56,) -> 48
B9: Arya Gupta | C9: 84 | D9: 79 | E9: 81 | F9: 86 | G9: 83 | H9: =SUM(Table19[[#This Row],[OS]:[TC]]) -> 413 | I9: =Table19[[#This Row],[Total]]/5 -> 82.6 | J9: =IF(Table19[[#This Row],[%]]>60,"Pass","Fail") -> Pass | K9: =IF(I10>=90,"A",IF(I10>=60,"B",IF(I10>=50,"C",IF(I10>=30,"D","F")))) -> B | L9: =RANK(I9,$I$5:$I$56,) -> 22
B10: Vihaan Mehta | C10: 73 | D10: 76 | E10: 71 | F10: 75 | G10: 78 | H10: =SUM(Table19[[#This Row],[OS]:[TC]]) -> 373 | I10: =Table19[[#This Row],[Total]]/5 -> 74.6 | J10: =IF(Table19[[#This Row],[%]]>60,"Pass","Fail") -> Pass | K10: =IF(I11>=90,"A",IF(I11>=60,"B",IF(I11>=50,"C",IF(I11>=30,"D","F")))) -> A | L10: =RANK(I10,$I$5:$I$56,) -> 30
B11: Siya Kapoor | C11: 88 | D11: 92 | E11: 90 | F11: 91 | G11: 89 | H11: =SUM(Table19[[#This Row],[OS]:[TC]]) -> 450 | I11: =Table19[[#This Row],[Total]]/5 -> 90 | J11: =IF(Table19[[#This Row],[%]]>60,"Pass","Fail") -> Pass | K11: =IF(I12>=90,"A",IF(I12>=60,"B",IF(I12>=50,"C",IF(I12>=30,"D","F")))) -> B | L11: =RANK(I11,$I$5:$I$56,) -> 13
B12: Aditya Jain | C12: 67 | D12: 70 | E12: 68 | F12: 72 | G12: 69 | H12: =SUM(Table19[[#This Row],[OS]:[TC]]) -> 346 | I12: =Table19[[#This Row],[Total]]/5 -> 69.2 | J12: =IF(Table19[[#This Row],[%]]>60,"Pass","Fail") -> Pass | K12: =IF(I13>=90,"A",IF(I13>=60,"B",IF(I13>=50,"C",IF(I13>=30,"D","F")))) -> A | L12: =RANK(I12,$I$5:$I$56,) -> 37
B13: Anaya Roy | C13: 95 | D13: 93 | E13: 97 | F13: 96 | G13: 94 | H13: =SUM(Table19[[#This Row],[OS]:[TC]]) -> 475 | I13: =Table19[[#This Row],[Total]]/5 -> 95 | J13: =IF(Table19[[#This Row],[%]]>60,"Pass","Fail") -> Pass | K13: =IF(I14>=90,"A",IF(I14>=60,"B",IF(I14>=50,"C",IF(I14>=30,"D","F")))) -> B | L13: =RANK(I13,$I$5:$I$56,) -> 5
B14: Krish Malhotra | C14: 58 | D14: 63 | E14: 60 | F14: 65 | G14: 62 | H14: =SUM(Table19[[#This Row],[OS]:[TC]]) -> 308 | I14: =Table19[[#This Row],[Total]]/5 -> 61.6 | J14: =IF(Table19[[#This Row],[%]]>60,"Pass","Fail") -> Pass | K14: =IF(I15>=90,"A",IF(I15>=60,"B",IF(I15>=50,"C",IF(I15>=30,"D","F")))) -> B | L14: =RANK(I14,$I$5:$I$56,) -> 45
B15: Ishita Sharma | C15: 81 | D15: 85 | E15: 83 | F15: 80 | G15: 84 | H15: =SUM(Table19[[#This Row],[OS]:[TC]]) -> 413 | I15: =Table19[[#This Row],[Total]]/5 -> 82.6 | J15: =IF(Table19[[#This Row],[%]]>60,"Pass","Fail") -> Pass | K15: =IF(I16>=90,"A",IF(I16>=60,"B",IF(I16>=50,"C",IF(I16>=30,"D","F")))) -> B | L15: =RANK(I15,$I$5:$I$56,) -> 22
B16: Arjun Nair | C16: 74 | D16: 77 | E16: 79 | F16: 76 | G16: 75 | H16: =SUM(Table19[[#This Row],[OS]:[TC]]) -> 381 | I16: =Table19[[#This Row],[Total]]/5 -> 76.2 | J16: =IF(Table19[[#This Row],[%]]>60,"Pass","Fail") -> Pass | K16: =IF(I17>=90,"A",IF(I17>=60,"B",IF(I17>=50,"C",IF(I17>=30,"D","F")))) -> B | L16: =RANK(I16,$I$5:$I$56,) -> 27
B17: Meera Joshi | C17: 90 | D17: 87 | E17: 91 | F17: 88 | G17: 89 | H17: =SUM(Table19[[#This Row],[OS]:[TC]]) -> 445 | I17: =Table19[[#This Row],[Total]]/5 -> 89 | J17: =IF(Table19[[#This Row],[%]]>60,"Pass","Fail") -> Pass | K17: =IF(I18>=90,"A",IF(I18>=60,"B",IF(I18>=50,"C",IF(I18>=30,"D","F")))) -> B | L17: =RANK(I17,$I$5:$I$56,) -> 15
... B53: Aarav Jain | C53: 97 | D53: 95 | E53: 98 | F53: 96 | G53: 99 | H53: =SUM(Table19[[#This Row],[OS]:[TC]]) -> 485 | I53: =Table19[[#This Row],[Total]]/5 -> 97 | J53: =IF(Table19[[#This Row],[%]]>60,"Pass","Fail") -> Pass | K53: =IF(I54>=90,"A",IF(I54>=60,"B",IF(I54>=50,"C",IF(I54>=30,"D","F")))) -> B | L53: =RANK(I53,$I$5:$I$56,) -> 1
B54: Tanish Batra | C54: 62 | D54: 64 | E54: 63 | F54: 65 | G54: 66 | H54: =SUM(Table19[[#This Row],[OS]:[TC]]) -> 320 | I54: =Table19[[#This Row],[Total]]/5 -> 64 | J54: =IF(Table19[[#This Row],[%]]>60,"Pass","Fail") -> Pass | K54: =IF(H56>=90,"A",IF(H56>=60,"B",IF(H56>=50,"C",IF(H56>=30,"D","F")))) -> B | L54: =RANK(I54,$I$5:$I$56,) -> 43
B55: Highest Marks | H55: =MAX(Table19[Total]) -> 475
B56: Average | H56: =AVERAGE(I5:I54) -> 78.86
B57: Total | K57: =SUBTOTAL(103,Table19[Grade]) -> 50

Sheet Sheet3

Sheet Expense Tracker
E2: PERSONAL EXPENSE TRACKER DASHBOARD
I3: SUMMARY TABLE
A4: Date | B4: Items | C4: Amount spend | D4: Payment Method | E4: Category
A5: 46166 | B5: Smart Watch Strap | C5: 450 | D5: UPI | E5: Accessories | H5: Parameters | I5: Values
A6: 46146 | B6: Notebook | C6: 120 | D6: Cash | E6: Education | H6: Income | I6: 30000
A7: 46164 | B7: Book | C7: 499 | D7: Debit Card | E7: Education | H7: Total Expense | I7: =SUBTOTAL(9,C5:C34) -> 23726
A8: 46150 | B8: Headphones | C8: 1599 | D8: Credit Card | E8: Electronics | H8: Average Expense | I8: =AVERAGE(C5:C33) -> 711.24138
A9: 46155 | B9: Pen Drive | C9: 650 | D9: UPI | E9: Electronics | H9: Highest Expense | I9: =MAX(C5:C34) -> 3100
A10: 46161 | B10: Laptop Mouse | C10: 799 | D10: UPI | E10: Electronics | H10: Lowest Expense | I10: =MIN(C5:C34) -> 120
A11: 46167 | B11: Data Cable | C11: 299 | D11: Cash | E11: Electronics | H11: Total Savings | I11: =30000-I7 -> 6274
A12: 46144 | B12: Movie Ticket | C12: 350 | D12: Credit Card | E12: Entertainment | H12: Budget remaining | I12: =I13-I7 -> 1274
A13: 46159 | B13: Netflix Subscription | C13: 649 | D13: Credit Card | E13: Entertainment | H13: Budget Limit | I13: 25000
A14: 46151 | B14: Gym Fee | C14: 1200 | D14: UPI | E14: Fitness | H14: Most used payment method | I14: UPI
A15: 46158 | B15: Protein Shake | C15: 2200 | D15: Debit Card | E15: Fitness
A16: 46143 | B16: Groceries | C16: 1450 | D16: UPI | E16: Food
A17: 46145 | B17: Pizza | C17: 499 | D17: UPI | E17: Food | I17: CATEGORY ANALYSIS TABLE
A18: 46148 | B18: Coffee | C18: 180 | D18: Cash | E18: Food
A19: 46152 | B19: Burger Meal | C19: 275 | D19: Cash | E19: Food | H19: Category | I19: Total Spend
A20: 46156 | B20: Ice Cream | C20: 150 | D20: Cash | E20: Food | H20: Education | I20: =SUMIF($E$5:$E$34,H20,$C$5:$C$34) -> 619
A21: 46162 | B21: Sandwich | C21: 140 | D21: Cash | E21: Food | H21: Electronics | I21: =SUMIF($E$5:$E$34,H21,$C$5:$C$34) -> 3347
A22: 46168 | B22: Biryani | C22: 390 | D22: UPI | E22: Food | H22: Entertainment | I22: =SUMIF($E$5:$E$34,H22,$C$5:$C$34) -> 999
A23: 46165 | B23: Shampoo | C23: 320 | D23: Cash | E23: Personal Care | H23: Fitness | I23: =SUMIF($E$5:$E$34,H23,$C$5:$C$34) -> 3400
A24: 46170 | B24: Face Wash | C24: 260 | D24: Debit Card | E24: Personal Care | H24: Food | I24: =SUMIF($E$5:$E$34,H24,$C$5:$C$34) -> 3084
A25: 46148 | B25: Shoes | C25: 2499 | D25: Debit Card | E25: Shopping | H25: Personal Care | I25: =SUMIF($E$5:$E$34,H25,$C$5:$C$34) -> 580
A26: 46153 | B26: T-shirt | C26: 899 | D26: Debit Card | E26: Shopping | H26: Shopping | I26: =SUMIF($E$5:$E$34,H26,$C$5:$C$34) -> 3748
A27: 46160 | B27: Water Bottle | C27: 350 | D27: Cash | E27: Shopping | H27: Transport | I27: =SUMIF($E$5:$E$34,H27,$C$5:$C$34) -> 3140
A28: 46169 | B28: Cricket Bat Grip | C28: 180 | D28: Cash | E28: Sports | H28: Utilities | I28: =SUMIF($E$5:$E$34,H28,$C$5:$C$34) -> 3399
A29: 46145 | B29: Petrol | C29: 2200 | D29: Cash | E29: Transport | H29: Travel | I29: =SUMIF($E$5:$E$34,H29,$C$5:$C$34) -> 780
A30: 46149 | B30: Uber Ride | C30: 340 | D30: UPI | E30: Transport | H30: Sports | I30: =SUMIF($E$5:$E$34,H30,$C$5:$C$34) -> 180
A31: 46163 | B31: Bus Pass | C31: 600 | D31: UPI | E31: Transport | H31: Accessories | I31: =SUMIF($E$5:$E$34,H31,$C$5:$C$34) -> 450
A32: 46157 | B32: Train Ticket | C32: 780 | D32: UPI | E32: Travel
A33: 46147 | B33: Mobile Recharge | C33: 299 | D33: UPI | E33: Utilities
A34: 46154 | B34: Electricity Bill | C34: 3100 | D34: Net Banking | E34: Utilities

Sheet Sales Dashboard
V11: D

Sheet Pivot Tables
X8: Row Labels | Y8: Sum of Sales Amount | AE8: Row Labels | AF8: Sum of Sales Amount
X9: Jan | Y9: 59880.9 | AE9: Bank Transfer | AF9: 207587.16
X10: Feb | Y10: 43409.2 | AE10: Cash | AF10: 117172.94
X11: Mar | Y11: 45592.06 | AE11: Credit Card | AF11: 140268.12
X12: Apr | Y12: 8417.51 | AE12: Grand Total | AF12: 465028.22
X13: May | Y13: 42683.04
X14: Jun | Y14: 37935.56
X15: Jul | Y15: 19600.04
X16: Aug | Y16: 17005.5
X17: Sep | Y17: 46822.04
X18: Oct | Y18: 36769.22 | AE18: Row Labels | AF18: Sum of Sales Amount
X19: Nov | Y19: 71326.75 | AE19: East | AF19: 136555.76
X20: Dec | Y20: 35586.4 | AE20: North | AF20: 122850.73
X21: Grand Total | Y21: 465028.22 | AE21: South | AF21: 97543.45
AE22: West | AF22: 108078.28
AE23: Grand Total | AF23: 465028.22
AB28: Row Labels | AC28: Sum of Sales Amount
AB29: Clothing | AC29: 128353.59
AB30: Electronics | AC30: 82097.49
AB31: Food | AC31: 125832.25
AB32: Furniture | AC32: 128744.89
AB33: Grand Total | AC33: 465028.22

Sheet Sheet8
A3: Row Labels | B3: Sum of Sales Amount
A4: Online | B4: 226359.01
A5: Retail | B5: 238669.21
A6: Grand Total | B6: 465028.22

Sheet Raw_Data
A4: Order ID | B4: Date | C4: Sales Rep | D4: Region | E4: Sales Amount | F4: Quantity | G4: Category | H4: Unit_Price | I4: Discount | J4: Payment Method | K4: Month | L4: Year | M4: Profit Margin | N4: Profit | O4: Sales Channel
A5: 1052 | B5: 44960 | C5: Bob | D5: North | E5: 5053.97 | F5: 18 | G5: Furniture | H5: 267.22 | I5: 0.09 | J5: Cash | K5: =TEXT(B5,"mmm") -> Feb | L5: =YEAR(B5) -> 2023 | M5: 0.25 | N5: =E5*25% -> 1263.4925 | O5: Online
A6: 1093 | B6: 45037 | C6: Bob | D6: West | E6: 4384.02 | F6: 17 | G6: Furniture | H6: 4209.44 | I6: 0.11 | J6: Cash | K6: =TEXT(B6,"mmm") -> Apr | L6: =YEAR(B6) -> 2023 | M6: 0.25 | N6: =E6*25% -> 1096.005 | O6: Retail
A7: 1015 | B7: 45190 | C7: David | D7: South | E7: 4631.23 | F7: 30 | G7: Food | H7: 371.4 | I7: 0.2 | J7: Bank Transfer | K7: =TEXT(B7,"mmm") -> Sep | L7: =YEAR(B7) -> 2023 | M7: 0.25 | N7: =E7*25% -> 1157.8075 | O7: Retail
A8: 1072 | B8: 45162 | C8: Bob | D8: South | E8: 2167.94 | F8: 39 | G8: Clothing | H8: 4467.75 | I8: 0.02 | J8: Credit Card | K8: =TEXT(B8,"mmm") -> Aug | L8: =YEAR(B8) -> 2023 | M8: 0.25 | N8: =E8*25% -> 541.985 | O8: Retail
A9: 1061 | B9: 45009 | C9: Charlie | D9: East | E9: 3750.2 | F9: 13 | G9: Electronics | H9: 692.71 | I9: 0.08 | J9: Credit Card | K9: =TEXT(B9,"mmm") -> Mar | L9: =YEAR(B9) -> 2023 | M9: 0.25 | N9: =E9*25% -> 937.55 | O9: Online
A10: 1021 | B10: 44968 | C10: Charlie | D10: West | E10: 3761.15 | F10: 32 | G10: Food | H10: 1106.51 | I10: 0.21 | J10: Cash | K10: =TEXT(B10,"mmm") -> Feb | L10: =YEAR(B10) -> 2023 | M10: 0.25 | N10: =E10*25% -> 940.2875 | O10: Online
A11: 1083 | B11: 45027 | C11: Bob | D11: West | E11: 618.31 | F11: 29 | G11: Furniture | H11: 2624.09 | I11: 0.14 | J11: Cash | K11: =TEXT(B11,"mmm") -> Apr | L11: =YEAR(B11) -> 2023 | M11: 0.25 | N11: =E11*25% -> 154.5775 | O11: Online
A12: 1087 | B12: 44932 | C12: Eve | D12: South | E12: 7698.92 | F12: 46 | G12: Furniture | H12: 3964.65 | I12: 0.12 | J12: Bank Transfer | K12: =TEXT(B12,"mmm") -> Jan | L12: =YEAR(B12) -> 2023 | M12: 0.25 | N12: =E12*25% -> 1924.73 | O12: Online
A13: 1075 | B13: 45106 | C13: David | D13: South | E13: 4223.39 | F13: 30 | G13: Furniture | H13: 1095.45 | I13: 0.05 | J13: Bank Transfer | K13: =TEXT(B13,"mmm") -> Jun | L13: =YEAR(B13) -> 2023 | M13: 0.25 | N13: =E13*25% -> 1055.8475 | O13: Online
A14: 1088 | B14: 45246 | C14: Eve | D14: North | E14: 8518.45 | F14: 13 | G14: Furniture | H14: 2517.6 | I14: 0.23 | J14: Bank Transfer | K14: =TEXT(B14,"mmm") -> Nov | L14: =YEAR(B14) -> 2023 | M14: 0.25 | N14: =E14*25% -> 2129.6125 | O14: Retail
A15: 1100 | B15: 45152 | C15: Bob | D15: West | E15: 2198.74 | F15: 43 | G15: Food | H15: 1137.44 | I15: 0.08 | J15: Bank Transfer | K15: =TEXT(B15,"mmm") -> Aug | L15: =YEAR(B15) -> 2023 | M15: 0.25 | N15: =E15*25% -> 549.685 | O15: Online
A16: 1024 | B16: 45241 | C16: Eve | D16: West | E16: 6607.8 | F16: 21 | G16: Food | H16: 641.09 | I16: 0 | J16: Bank Transfer | K16: =TEXT(B16,"mmm") -> Nov | L16: =YEAR(B16) -> 2023 | M16: 0.25 | N16: =E16*25% -> 1651.95 | O16: Retail
... A104: 1010 | B104: 44973 | C104: David | D104: East | E104: 1678.97 | F104: 47 | G104: Furniture | H104: 2429.93 | I104: 0.06 | J104: Bank Transfer | K104: =TEXT(B104,"mmm") -> Feb | L104: =YEAR(B104) -> 2023 | M104: 0.25 | N104: =E104*25% -> 419.7425 | O104: Online

Sheet 20
A1: MAKE A PIVOTTABLE FROM SCRATCH
A2: Cells B15 through E22 contain Data. There are four columns: Date, Buyer, Type, and Amount. Each column has various values for each row.
A3: 1. Navigate to any of the data cells.
A4: 2. Remember that after step 4, a new sheet will be created. And when that happens, remember to use ALT+JT, L to open the PivotTable Fields List if it's not open already. Then add the Amount field to the Values area, and Buyer to the Rows area.
A5: 3. Press ALT+N,V to access the Create PivotTable dialog box.
A6: 4. Press ENTER to accept the default options.
A7: To continue with this tutorial, press CTRL+PAGE DOWN. To go to the previous sheet, press CTRL+PAGE UP.
B15: Date | C15: Buyer | D15: Type | E15: Amount
B16: 42736 | C16: Mom | D16: Fuel | E16: 74
B17: 42750 | C17: Mom | D17: Food | E17: 235
B18: 42752 | C18: Dad | D18: Sports | E18: 20
B19: 42756 | C19: Kelly | D19: Books | E19: 125
B20: 42768 | C20: Mom | D20: Food | E20: 235
B21: 42786 | C21: Kelly | D21: Music | E21: 20
B22: 42791 | C22: Kelly | D22: Tickets | E22: 125

Sheet Learn more
A1: Good job. You made it.
A2: But keep going! There's more to learn…
A3: More Pivot info: Discover more you can do by reading this helpful article on PivotTables.
A4: Clean data is key: Excel can help. Check out this article to learn more about Get & Transform.
A5: LinkedIn Learning: Video courses for all levels—from beginner to advanced. Take at your own pace.
A6: Community: Connect with other Excel fans. They can help you, and you can help them.
